Workbook

Sheet Config
A1: DUHA INTERNATIONAL SCHOOL — CONFIGURATION PANEL
A2: INSTRUCTIONS: (1) Staff Roster — add/remove staff rows freely. (2) Leave Types — add/remove leave types and set annual days. Max 5 types. (3) Settings — change Report Year only. Blue cells are auto-filled. Yellow cells are editable.
A4: STAFF ROSTER | E4: LEAVE TYPES | H4: SETTINGS
A5: Add or remove staff rows. Delete row content to remove a staff member. | E5: Add/remove leave types. Annual Days = days allowed per year. | H5: Change Report Year to switch annual view in Monthly Breakdown.
A6: # | B6: Staff Name | C6: Designation | E6: Leave Type Name | F6: Annual Days | H6: Setting | I6: Value
A7: =IF(B7="","",ROW()-6) -> 1 | B7: Hasan Mahmud | C7: Director | E7: Casual Leave | F7: 10 | H7: Report Year | I7: 2026
A8: =IF(B8="","",ROW()-6) -> 2 | B8: Hasina Mohammed | C8: Principal | E8: Special Leave | F8: 5 | H8: School Name | I8: Duha International School
A9: =IF(B9="","",ROW()-6) -> 3 | B9: Nusrat Jahan Ira | H9: Prepared By | I9: Principal / Admin
A10: =IF(B10="","",ROW()-6) -> 4 | B10: Sadia Sultana Rima | C10: Preschool Co-ordinator
A11: =IF(B11="","",ROW()-6) -> 5 | B11: Fatema Akter Mili
A12: =IF(B12="","",ROW()-6) -> 6 | B12: Farida Yesmin Tamanna | E12: ↑ Max 5 leave types.
A13: =IF(B13="","",ROW()-6) -> 7 | B13: Shalina Akter Eity
A14: =IF(B14="","",ROW()-6) -> 8 | B14: Rabia Sultana Prity | C14: Class Teacher
A15: =IF(B15="","",ROW()-6) -> 9 | B15: Afrin Jahan Uzma | C15: Lead Teacher
A16: =IF(B16="","",ROW()-6) -> 10 | B16: Ariful Islam Maruf
A17: =IF(B17="","",ROW()-6) -> 11 | B17: Jinat Farhana Chy | C17: Asst. Co-ord. (Pre-School)
A18: =IF(B18="","",ROW()-6) -> 12 | B18: Tabassuma Barat Chowdhury | C18: Primary Co-ordinator
A19: =IF(B19="","",ROW()-6) -> 13 | B19: Sumaya Rahman | C19: Asst. Co-ord. (Secondary)
A20: =IF(B20="","",ROW()-6) -> 14 | B20: Warda Siraj | C20: Head Of BC
A21: =IF(B21="","",ROW()-6) -> 15 | B21: Irfan Hossain
A22: =IF(B22="","",ROW()-6) -> 16 | B22: Mohoshina Shifa Buble | C22: Teacher's Assistant
A23: =IF(B23="","",ROW()-6) -> 17 | B23: Sadia Akter Lubna | C23: Teacher's Assistant
A24: =IF(B24="","",ROW()-6) -> 18 | B24: Taslima Akter | C24: Subject Teacher (IC)
A25: =IF(B25="","",ROW()-6) -> 19 | B25: Samiya Hashem | C25: Teacher's Assistant
A26: =IF(B26="","",ROW()-6) -> 20 | B26: Humaira Tasnim
A27: =IF(B27="","",ROW()-6) -> 21 | B27: Aziza Sultana | C27: Teacher's Assistant
A28: =IF(B28="","",ROW()-6) -> 22 | B28: Farhana Yesmin
A29: =IF(B29="","",ROW()-6) -> 23 | B29: Kamrun Nahar | C29: Class Teacher
A30: =IF(B30="","",ROW()-6) -> 24 | B30: Tashmem Al Faed | C30: Subject Teacher
A31: =IF(B31="","",ROW()-6) -> 25 | B31: Md Murad Hoshen | C31: IC Co-ordinator
A32: =IF(B32="","",ROW()-6) -> 26 | B32: Najmul Haque Masum | C32: Subject Teacher (IC)
A33: =IF(B33="","",ROW()-6) -> 27 | B33: Rahnuman Nesa Chowdhury | C33: Class Teacher
A34: =IF(B34="","",ROW()-6) -> 28 | B34: Othora Nausin Jafrin | C34: Assistant Teacher
A35: =IF(B35="","",ROW()-6) -> 29 | B35: Md Rahat Chy
A36: =IF(B36="","",ROW()-6) -> 30 | B36: Sania Rahman | C36: Class Teacher
A37: =IF(B37="","",ROW()-6) -> 31 | B37: Jaharin Subah | C37: Class Teacher
A38: =IF(B38="","",ROW()-6) -> 32 | B38: Afroza Akter
A39: =IF(B39="","",ROW()-6) -> 33 | B39: Ummay Hani Juthi | C39: Lead Teacher
A40: =IF(B40="","",ROW()-6) -> 34 | B40: Tanzina Haque | C40: Subject Teacher
A41: =IF(B41="","",ROW()-6) -> 35 | B41: Tahsina Tarannum
...

Sheet Leave Records
A1: DUHA INTERNATIONAL SCHOOL — LEAVE RECORDS
A2: FILL IN (white cells): Staff Name ▼ Leave Type ▼ Reason From Date To Date Days Request Date Status ▼ | AUTO-FILLED (blue cells): SL# Designation Month
A3: SL# | B3: Staff Name | C3: Designation | D3: Leave Type | E3: Reason | F3: From Date | G3: To Date | H3: Month | I3: Days | J3: Request Date | K3: Status
A4: =IF(B4="","",ROW()-3) -> 1 | B4: Hasina Mohammed | C4: =IFERROR(VLOOKUP(B4,Config!$B$7:$C$106,2,0),"") -> Principal | D4: Casual Leave | E4: March CL | F4: 46082 | G4: 46083 | H4: =IF(F4="","",TEXT(F4,"MMMM YYYY")) -> March 2026 | I4: 2 | J4: 46082 | K4: Approved
A5: =IF(B5="","",ROW()-3) -> 2 | B5: Farida Yesmin Tamanna | C5: =IFERROR(VLOOKUP(B5,Config!$B$7:$C$106,2,0),"") | D5: Casual Leave | E5: March CL | F5: 46082 | G5: 46083 | H5: =IF(F5="","",TEXT(F5,"MMMM YYYY")) -> March 2026 | I5: 2 | J5: 46082 | K5: Approved
A6: =IF(B6="","",ROW()-3) -> 3 | B6: Rabia Sultana Prity | C6: =IFERROR(VLOOKUP(B6,Config!$B$7:$C$106,2,0),"") -> Class Teacher | D6: Casual Leave | E6: March CL | F6: 46082 | G6: 46086 | H6: =IF(F6="","",TEXT(F6,"MMMM YYYY")) -> March 2026 | I6: 5 | J6: 46082 | K6: Approved
A7: =IF(B7="","",ROW()-3) -> 4 | B7: Afrin Jahan Uzma | C7: =IFERROR(VLOOKUP(B7,Config!$B$7:$C$106,2,0),"") -> Lead Teacher | D7: Casual Leave | E7: March CL | F7: 46082 | G7: 46082 | H7: =IF(F7="","",TEXT(F7,"MMMM YYYY")) -> March 2026 | I7: 1 | J7: 46082 | K7: Approved
A8: =IF(B8="","",ROW()-3) -> 5 | B8: Ariful Islam Maruf | C8: =IFERROR(VLOOKUP(B8,Config!$B$7:$C$106,2,0),"") | D8: Casual Leave | E8: March CL | F8: 46082 | G8: 46083 | H8: =IF(F8="","",TEXT(F8,"MMMM YYYY")) -> March 2026 | I8: 2 | J8: 46082 | K8: Approved
A9: =IF(B9="","",ROW()-3) -> 6 | B9: Jinat Farhana Chy | C9: =IFERROR(VLOOKUP(B9,Config!$B$7:$C$106,2,0),"") -> Asst. Co-ord. (Pre-School) | D9: Casual Leave | E9: March CL | F9: 46082 | G9: 46082 | H9: =IF(F9="","",TEXT(F9,"MMMM YYYY")) -> March 2026 | I9: 1 | J9: 46082 | K9: Approved
A10: =IF(B10="","",ROW()-3) -> 7 | B10: Irfan Hossain | C10: =IFERROR(VLOOKUP(B10,Config!$B$7:$C$106,2,0),"") | D10: Casual Leave | E10: March CL | F10: 46082 | G10: 46085 | H10: =IF(F10="","",TEXT(F10,"MMMM YYYY")) -> March 2026 | I10: 4 | J10: 46082 | K10: Approved
A11: =IF(B11="","",ROW()-3) -> 8 | B11: Mohoshina Shifa Buble | C11: =IFERROR(VLOOKUP(B11,Config!$B$7:$C$106,2,0),"") -> Teacher's Assistant | D11: Casual Leave | E11: March CL | F11: 46082 | G11: 46084 | H11: =IF(F11="","",TEXT(F11,"MMMM YYYY")) -> March 2026 | I11: 3 | J11: 46082 | K11: Approved
A12: =IF(B12="","",ROW()-3) -> 9 | B12: Taslima Akter | C12: =IFERROR(VLOOKUP(B12,Config!$B$7:$C$106,2,0),"") -> Subject Teacher (IC) | D12: Casual Leave | E12: March CL | F12: 46082 | G12: 46083 | H12: =IF(F12="","",TEXT(F12,"MMMM YYYY")) -> March 2026 | I12: 2 | J12: 46082 | K12: Approved
A13: =IF(B13="","",ROW()-3) -> 10 | B13: Humaira Tasnim | C13: =IFERROR(VLOOKUP(B13,Config!$B$7:$C$106,2,0),"") | D13: Casual Leave | E13: March CL | F13: 46082 | G13: 46088 | H13: =IF(F13="","",TEXT(F13,"MMMM YYYY")) -> March 2026 | I13: 7 | J13: 46082 | K13: Approved
A14: =IF(B14="","",ROW()-3) -> 11 | B14: Aziza Sultana | C14: =IFERROR(VLOOKUP(B14,Config!$B$7:$C$106,2,0),"") -> Teacher's Assistant | D14: Casual Leave | E14: March CL | F14: 46082 | G14: 46083 | H14: =IF(F14="","",TEXT(F14,"MMMM YYYY")) -> March 2026 | I14: 2 | J14: 46082 | K14: Approved
A15: =IF(B15="","",ROW()-3) -> 12 | B15: Farhana Yesmin | C15: =IFERROR(VLOOKUP(B15,Config!$B$7:$C$106,2,0),"") | D15: Casual Leave | E15: March CL | F15: 46082 | G15: 46082 | H15: =IF(F15="","",TEXT(F15,"MMMM YYYY")) -> March 2026 | I15: 1 | J15: 46082 | K15: Approved
... A77: =IF(B77="","",ROW()-3) -> 74 | B77: Sultana Yasmin Geeti | C77: =IFERROR(VLOOKUP(B77,Config!$B$7:$C$106,2,0),"") | D77: Casual Leave | E77: Absent on 12th counted as CL | F77: 46154 | G77: 46154 | H77: =IF(F77="","",TEXT(F77,"MMMM YYYY")) -> May 2026 | I77: 1 | J77: 46154 | K77: Approved
A78: =IF(B78="","",ROW()-3) | C78: =IFERROR(VLOOKUP(B78,Config!$B$7:$C$106,2,0),"") | H78: =IF(F78="","",TEXT(F78,"MMMM YYYY"))
A79: =IF(B79="","",ROW()-3) | C79: =IFERROR(VLOOKUP(B79,Config!$B$7:$C$106,2,0),"") | H79: =IF(F79="","",TEXT(F79,"MMMM YYYY"))
A80: =IF(B80="","",ROW()-3) | C80: =IFERROR(VLOOKUP(B80,Config!$B$7:$C$106,2,0),"") | H80: =IF(F80="","",TEXT(F80,"MMMM YYYY"))
A81: =IF(B81="","",ROW()-3) | C81: =IFERROR(VLOOKUP(B81,Config!$B$7:$C$106,2,0),"") | H81: =IF(F81="","",TEXT(F81,"MMMM YYYY"))
A82: =IF(B82="","",ROW()-3) | C82: =IFERROR(VLOOKUP(B82,Config!$B$7:$C$106,2,0),"") | H82: =IF(F82="","",TEXT(F82,"MMMM YYYY"))
A83: =IF(B83="","",ROW()-3) | C83: =IFERROR(VLOOKUP(B83,Config!$B$7:$C$106,2,0),"") | H83: =IF(F83="","",TEXT(F83,"MMMM YYYY"))
A84: =IF(B84="","",ROW()-3) | C84: =IFERROR(VLOOKUP(B84,Config!$B$7:$C$106,2,0),"") | H84: =IF(F84="","",TEXT(F84,"MMMM YYYY"))
A85: =IF(B85="","",ROW()-3) | C85: =IFERROR(VLOOKUP(B85,Config!$B$7:$C$106,2,0),"") | H85: =IF(F85="","",TEXT(F85,"MMMM YYYY"))
A86: =IF(B86="","",ROW()-3) | C86: =IFERROR(VLOOKUP(B86,Config!$B$7:$C$106,2,0),"") | H86: =IF(F86="","",TEXT(F86,"MMMM YYYY"))
A87: =IF(B87="","",ROW()-3) | C87: =IFERROR(VLOOKUP(B87,Config!$B$7:$C$106,2,0),"") | H87: =IF(F87="","",TEXT(F87,"MMMM YYYY"))
A88: =IF(B88="","",ROW()-3) | C88: =IFERROR(VLOOKUP(B88,Config!$B$7:$C$106,2,0),"") | H88: =IF(F88="","",TEXT(F88,"MMMM YYYY"))
A89: =IF(B89="","",ROW()-3) | C89: =IFERROR(VLOOKUP(B89,Config!$B$7:$C$106,2,0),"") | H89: =IF(F89="","",TEXT(F89,"MMMM YYYY"))
... A303: =IF(B303="","",ROW()-3) | C303: =IFERROR(VLOOKUP(B303,Config!$B$7:$C$106,2,0),"") | H303: =IF(F303="","",TEXT(F303,"MMMM YYYY"))
A304: ← 300 rows pre-formatted above. Insert rows before this line to add more.
A305: =IF(B305="","",ROW()-3) -> 302 | B305: Tahsina Tarannum | C305: =IFERROR(VLOOKUP(B305,Config!$B$7:$C$106,2,0),"") | D305: Special Leave | E305: My grandfather was sick a few month sudden he left.. | F305: 46182.5 | G305: 46182.5 | H305: =IF(F305="","",TEXT(F305,"MMMM YYYY")) -> June 2026 | I305: 1 | J305: 46182.5 | K305: Approved
A306: =IF(B306="","",ROW()-3) -> 303 | B306: Jinat Farhana Chy | C306: =IFERROR(VLOOKUP(B306,Config!$B$7:$C$106,2,0),"") -> Asst. Co-ord. (Pre-School) | D306: Casual Leave | E306: Tonsil infections and fever. | F306: 46181.5 | G306: 46181.5 | H306: =IF(F306="","",TEXT(F306,"MMMM YYYY")) -> June 2026 | I306: 1 | J306: 46181.5 | K306: Approved
A307: =IF(B307="","",ROW()-3) -> 304 | B307: Sumaya Rahman | C307: =IFERROR(VLOOKUP(B307,Config!$B$7:$C$106,2,0),"") -> Asst. Co-ord. (Secondary) | D307: Casual Leave | E307: Family need | F307: 46155.5 | G307: 46156.5 | H307: =IF(F307="","",TEXT(F307,"MMMM YYYY")) -> May 2026 | I307: 2 | J307: 46155.5 | K307: Approved
A308: =IF(B308="","",ROW()-3) -> 305 | B308: Sania Rahman | C308: =IFERROR(VLOOKUP(B308,Config!$B$7:$C$106,2,0),"") -> Class Teacher | D308: Casual Leave | E308: My mother is sick | F308: 46154.5 | G308: 46155.5 | H308: =IF(F308="","",TEXT(F308,"MMMM YYYY")) -> May 2026 | I308: 2 | J308: 46154.5 | K308: Approved
A309: =IF(B309="","",ROW()-3) -> 306 | B309: Hasan Mahmud | C309: =IFERROR(VLOOKUP(B309,Config!$B$7:$C$106,2,0),"") -> Director | D309: Casual Leave | F309: 46113.5 | G309: 46113.5 | H309: =IF(F309="","",TEXT(F309,"MMMM YYYY")) -> April 2026 | I309: 1 | J309: 46138.5 | K309: Cancelled

Sheet Leave Summary
A1: DUHA INTERNATIONAL SCHOOL — LEAVE SUMMARY
A2: READ ONLY — Auto-calculated from 'Leave Records'. To add staff: edit Config sheet. To add leave entries: edit Leave Records sheet.
A3: SL | B3: Staff Name | C3: Designation | D3: =IFERROR(IF(Config!$E$7="","— Not Set —",Config!$E$7),"— Not Set —") -> Casual Leave | H3: =IFERROR(IF(Config!$E$8="","— Not Set —",Config!$E$8),"— Not Set —") -> Special Leave | L3: =IFERROR(IF(Config!$E$9="","— Not Set —",Config!$E$9),"— Not Set —") -> — Not Set — | P3: =IFERROR(IF(Config!$E$10="","— Not Set —",Config!$E$10),"— Not Set —") -> — Not Set — | T3: =IFERROR(IF(Config!$E$11="","— Not Set —",Config!$E$11),"— Not Set —") -> — Not Set — | X3: Grand Total Approved
A4: SL | B4: Staff Name | C4: Designation | D4: Annual Allot. | E4: Days Approved | F4: Days Pending | G4: Balance (Allot-Apprv) | H4: Annual Allot. | I4: Days Approved | J4: Days Pending | K4: Balance (Allot-Apprv) | L4: Annual Allot. | M4: Days Approved | N4: Days Pending | O4: Balance (Allot-Apprv) | P4: Annual Allot. | Q4: Days Approved | R4: Days Pending | S4: Balance (Allot-Apprv) | T4: Annual Allot. | U4: Days Approved | V4: Days Pending | W4: Balance (Allot-Apprv) | X4: Total Approved
A5: =IF(B5="","",ROW()-4) -> 1 | B5: =IF(Config!$B$7="","",Config!$B$7) -> Hasan Mahmud | C5: =IF(Config!$B$7="","",Config!$C$7) -> Director | D5: =IF($B5="","",IFERROR(Config!$F$7,0)) -> 10 | E5: =IF($B5="","",IF(Config!$E$7="",0,SUMIFS('Leave Records'!$I:$I,'Leave Records'!$B:$B,$B5,'Leave Records'!$D:$D,Config!$E$7,'Leave Records'!$K:$K,"Approved"))) -> 0 | F5: =IF($B5="","",IF(Config!$E$7="",0,SUMIFS('Leave Records'!$I:$I,'Leave Records'!$B:$B,$B5,'Leave Records'!$D:$D,Config!$E$7,'Leave Records'!$K:$K,"Pending"))) -> 0 | G5: =IF($B5="","",D5-E5) -> 10 | H5: =IF($B5="","",IFERROR(Config!$F$8,0)) -> 5 | I5: =IF($B5="","",IF(Config!$E$8="",0,SUMIFS('Leave Records'!$I:$I,'Leave Records'!$B:$B,$B5,'Leave Records'!$D:$D,Config!$E$8,'Leave Records'!$K:$K,"Approved"))) -> 0 | J5: =IF($B5="","",IF(Config!$E$8="",0,SUMIFS('Leave Records'!$I:$I,'Leave Records'!$B:$B,$B5,'Leave Records'!$D:$D,Config!$E$8,'Leave Records'!$K:$K,"Pending"))) -> 0 | K5: =IF($B5="","",H5-I5) -> 5 | L5: =IF($B5="","",IFERROR(Config!$F$9,0)) -> 0 | M5: =IF($B5="","",IF(Config!$E$9="",0,SUMIFS('Leave Records'!$I:$I,'Leave Records'!$B:$B,$B5,'Leave Records'!$D:$D,Config!$E$9,'Leave Records'!$K:$K,"Approved"))) -> 0 | N5: =IF($B5="","",IF(Config!$E$9="",0,SUMIFS('Leave Records'!$I:$I,'Leave Records'!$B:$B,$B5,'Leave Records'!$D:$D,Config!$E$9,'Leave Records'!$K:$K,"Pending"))) -> 0 | O5: =IF($B5="","",L5-M5) -> 0 | P5: =IF($B5="","",IFERROR(Config!$F$10,0)) -> 0 | Q5: =IF($B5="","",IF(Config!$E$10="",0,SUMIFS('Leave Records'!$I:$I,'Leave Records'!$B:$B,$B5,'Leave Records'!$D:$D,Config!$E$10,'Leave Records'!$K:$K,"Approved"))) -> 0 | R5: =IF($B5="","",IF(Config!$E$10="",0,SUMIFS('Leave Records'!$I:$I,'Leave Records'!$B:$B,$B5,'Leave Records'!$D:$D,Config!$E$10,'Leave Records'!$K:$K,"Pending"))) -> 0 | S5: =IF($B5="","",P5-Q5) -> 0 | T5: =IF($B5="","",IFERROR(Config!$F$11,0)) -> 0 | U5: =IF($B5="","",IF(Config!$E$11="",0,SUMIFS('Leave Records'!$I:$I,'Leave Records'!$B:$B,$B5,'Leave Records'!$D:$D,Config!$E$11,'Leave Records'!$K:$K,"Approved"))) -> 0 | V5: =IF($B5="","",IF(Config!$E$11="",0,SUMIFS('Leave Records'!$I:$I,'Leave Records'!$B:$B,$B5,'Leave Records'!$D:$D,Config!$E$11,'Leave Records'!$K:$K,"Pending"))) -> 0 | W5: =IF($B5="","",T5-U5) -> 0 | X5: =IF($B5="","",E5+I5+M5+Q5+U5) -> 0
A6: =IF(B6="","",ROW()-4) -> 2 | B6: =IF(Config!$B$8="","",Config!$B$8) -> Hasina Mohammed | C6: =IF(Config!$B$8="","",Config!$C$8) -> Principal | D6: =IF($B6="","",IFERROR(Config!$F$7,0)) -> 10 | E6: =IF($B6="","",IF(Config!$E$7="",0,SUMIFS('Leave Records'!$I:$I,'Leave Records'!$B:$B,$B6,'Leave Records'!$D:$D,Config!$E$7,'Leave Records'!$K:$K,"Approved"))) -> 2 | F6: =IF($B6="","",IF(Config!$E$7="",0,SUMIFS('Leave Records'!$I:$I,'Leave Records'!$B:$B,$B6,'Leave Records'!$D:$D,Config!$E$7,'Leave Records'!$K:$K,"Pending"))) -> 0 | G6: =IF($B6="","",D6-E6) -> 8 | H6: =IF($B6="","",IFERROR(Config!$F$8,0)) -> 5 | I6: =IF($B6="","",IF(Config!$E$8="",0,SUMIFS('Leave Records'!$I:$I,'Leave Records'!$B:$B,$B6,'Leave Records'!$D:$D,Config!$E$8,'Leave Records'!$K:$K,"Approved"))) -> 0 | J6: =IF($B6="","",IF(Config!$E$8="",0,SUMIFS('Leave Records'!$I:$I,'Leave Records'!$B:$B,$B6,'Leave Records'!$D:$D,Config!$E$8,'Leave Records'!$K:$K,"Pending"))) -> 0 | K6: =IF($B6="","",H6-I6) -> 5 | L6: =IF($B6="","",IFERROR(Config!$F$9,0)) -> 0 | M6: =IF($B6="","",IF(Config!$E$9="",0,SUMIFS('Leave Records'!$I:$I,'Leave Records'!$B:$B,$B6,'Leave Records'!$D:$D,Config!$E$9,'Leave Records'!$K:$K,"Approved"))) -> 0 | N6: =IF($B6="","",IF(Config!$E$9="",0,SUMIFS('Leave Records'!$I:$I,'Leave Records'!$B:$B,$B6,'Leave Records'!$D:$D,Config!$E$9,'Leave Records'!$K:$K,"Pending"))) -> 0 | O6: =IF($B6="","",L6-M6) -> 0 | P6: =IF($B6="","",IFERROR(Config!$F$10,0)) -> 0 | Q6: =IF($B6="","",IF(Config!$E$10="",0,SUMIFS('Leave Records'!$I:$I,'Leave Records'!$B:$B,$B6,'Leave Records'!$D:$D,Config!$E$10,'Leave Records'!$K:$K,"Approved"))) -> 0 | R6: =IF($B6="","",IF(Config!$E$10="",0,SUMIFS('Leave Records'!$I:$I,'Leave Records'!$B:$B,$B6,'Leave Records'!$D:$D,Config!$E$10,'Leave Records'!$K:$K,"Pending"))) -> 0 | S6: =IF($B6="","",P6-Q6) -> 0 | T6: =IF($B6="","",IFERROR(Config!$F$11,0)) -> 0 | U6: =IF($B6="","",IF(Config!$E$11="",0,SUMIFS('Leave Records'!$I:$I,'Leave Records'!$B:$B,$B6,'Leave Records'!$D:$D,Config!$E$11,'Leave Records'!$K:$K,"Approved"))) -> 0 | V6: =IF($B6="","",IF(Config!$E$11="",0,SUMIFS('Leave Records'!$I:$I,'Leave Records'!$B:$B,$B6,'Leave Records'!$D:$D,Config!$E$11,'Leave Records'!$K:$K,"Pending"))) -> 0 | W6: =IF($B6="","",T6-U6) -> 0 | X6: =IF($B6="","",E6+I6+M6+Q6+U6) -> 2
A7: =IF(B7="","",ROW()-4) -> 3 | B7: =IF(Config!$B$9="","",Config!$B$9) -> Nusrat Jahan Ira | C7: =IF(Config!$B$9="","",Config!$C$9) | D7: =IF($B7="","",IFERROR(Config!$F$7,0)) -> 10 | E7: =IF($B7="","",IF(Config!$E$7="",0,SUMIFS('Leave Records'!$I:$I,'Leave Records'!$B:$B,$B7,'Leave Records'!$D:$D,Config!$E$7,'Leave Records'!$K:$K,"Approved"))) -> 0 | F7: =IF($B7="","",IF(Config!$E$7="",0,SUMIFS('Leave Records'!$I:$I,'Leave Records'!$B:$B,$B7,'Leave Records'!$D:$D,Config!$E$7,'Leave Records'!$K:$K,"Pending"))) -> 0 | G7: =IF($B7="","",D7-E7) -> 10 | H7: =IF($B7="","",IFERROR(Config!$F$8,0)) -> 5 | I7: =IF($B7="","",IF(Config!$E$8="",0,SUMIFS('Leave Records'!$I:$I,'Leave Records'!$B:$B,$B7,'Leave Records'!$D:$D,Config!$E$8,'Leave Records'!$K:$K,"Approved"))) -> 0 | J7: =IF($B7="","",IF(Config!$E$8="",0,SUMIFS('Leave Records'!$I:$I,'Leave Records'!$B:$B,$B7,'Leave Records'!$D:$D,Config!$E$8,'Leave Records'!$K:$K,"Pending"))) -> 0 | K7: =IF($B7="","",H7-I7) -> 5 | L7: =IF($B7="","",IFERROR(Config!$F$9,0)) -> 0 | M7: =IF($B7="","",IF(Config!$E$9="",0,SUMIFS('Leave Records'!$I:$I,'Leave Records'!$B:$B,$B7,'Leave Records'!$D:$D,Config!$E$9,'Leave Records'!$K:$K,"Approved"))) -> 0 | N7: =IF($B7="","",IF(Config!$E$9="",0,SUMIFS('Leave Records'!$I:$I,'Leave Records'!$B:$B,$B7,'Leave Records'!$D:$D,Config!$E$9,'Leave Records'!$K:$K,"Pending"))) -> 0 | O7: =IF($B7="","",L7-M7) -> 0 | P7: =IF($B7="","",IFERROR(Config!$F$10,0)) -> 0 | Q7: =IF($B7="","",IF(Config!$E$10="",0,SUMIFS('Leave Records'!$I:$I,'Leave Records'!$B:$B,$B7,'Leave Records'!$D:$D,Config!$E$10,'Leave Records'!$K:$K,"Approved"))) -> 0 | R7: =IF($B7="","",IF(Config!$E$10="",0,SUMIFS('Leave Records'!$I:$I,'Leave Records'!$B:$B,$B7,'Leave Records'!$D:$D,Config!$E$10,'Leave Records'!$K:$K,"Pending"))) -> 0 | S7: =IF($B7="","",P7-Q7) -> 0 | T7: =IF($B7="","",IFERROR(Config!$F$11,0)) -> 0 | U7: =IF($B7="","",IF(Config!$E$11="",0,SUMIFS('Leave Records'!$I:$I,'Leave Records'!$B:$B,$B7,'Leave Records'!$D:$D,Config!$E$11,'Leave Records'!$K:$K,"Approved"))) -> 0 | V7: =IF($B7="","",IF(Config!$E$11="",0,SUMIFS('Leave Records'!$I:$I,'Leave Records'!$B:$B,$B7,'Leave Records'!$D:$D,Config!$E$11,'Leave Records'!$K:$K,"Pending"))) -> 0 | W7: =IF($B7="","",T7-U7) -> 0 | X7: =IF($B7="","",E7+I7+M7+Q7+U7) -> 0
A8: =IF(B8="","",ROW()-4) -> 4 | B8: =IF(Config!$B$10="","",Config!$B$10) -> Sadia Sultana Rima | C8: =IF(Config!$B$10="","",Config!$C$10) -> Preschool Co-ordinator | D8: =IF($B8="","",IFERROR(Config!$F$7,0)) -> 10 | E8: =IF($B8="","",IF(Config!$E$7="",0,SUMIFS('Leave Records'!$I:$I,'Leave Records'!$B:$B,$B8,'Leave Records'!$D:$D,Config!$E$7,'Leave Records'!$K:$K,"Approved"))) -> 2 | F8: =IF($B8="","",IF(Config!$E$7="",0,SUMIFS('Leave Records'!$I:$I,'Leave Records'!$B:$B,$B8,'Leave Records'!$D:$D,Config!$E$7,'Leave Records'!$K:$K,"Pending"))) -> 0 | G8: =IF($B8="","",D8-E8) -> 8 | H8: =IF($B8="","",IFERROR(Config!$F$8,0)) -> 5 | I8: =IF($B8="","",IF(Config!$E$8="",0,SUMIFS('Leave Records'!$I:$I,'Leave Records'!$B:$B,$B8,'Leave Records'!$D:$D,Config!$E$8,'Leave Records'!$K:$K,"Approved"))) -> 1 | J8: =IF($B8="","",IF(Config!$E$8="",0,SUMIFS('Leave Records'!$I:$I,'Leave Records'!$B:$B,$B8,'Leave Records'!$D:$D,Config!$E$8,'Leave Records'!$K:$K,"Pending"))) -> 0 | K8: =IF($B8="","",H8-I8) -> 4 | L8: =IF($B8="","",IFERROR(Config!$F$9,0)) -> 0 | M8: =IF($B8="","",IF(Config!$E$9="",0,SUMIFS('Leave Records'!$I:$I,'Leave Records'!$B:$B,$B8,'Leave Records'!$D:$D,Config!$E$9,'Leave Records'!$K:$K,"Approved"))) -> 0 | N8: =IF($B8="","",IF(Config!$E$9="",0,SUMIFS('Leave Records'!$I:$I,'Leave Records'!$B:$B,$B8,'Leave Records'!$D:$D,Config!$E$9,'Leave Records'!$K:$K,"Pending"))) -> 0 | O8: =IF($B8="","",L8-M8) -> 0 | P8: =IF($B8="","",IFERROR(Config!$F$10,0)) -> 0 | Q8: =IF($B8="","",IF(Config!$E$10="",0,SUMIFS('Leave Records'!$I:$I,'Leave Records'!$B:$B,$B8,'Leave Records'!$D:$D,Config!$E$10,'Leave Records'!$K:$K,"Approved"))) -> 0 | R8: =IF($B8="","",IF(Config!$E$10="",0,SUMIFS('Leave Records'!$I:$I,'Leave Records'!$B:$B,$B8,'Leave Records'!$D:$D,Config!$E$10,'Leave Records'!$K:$K,"Pending"))) -> 0 | S8: =IF($B8="","",P8-Q8) -> 0 | T8: =IF($B8="","",IFERROR(Config!$F$11,0)) -> 0 | U8: =IF($B8="","",IF(Config!$E$11="",0,SUMIFS('Leave Records'!$I:$I,'Leave Records'!$B:$B,$B8,'Leave Records'!$D:$D,Config!$E$11,'Leave Records'!$K:$K,"Approved"))) -> 0 | V8: =IF($B8="","",IF(Config!$E$11="",0,SUMIFS('Leave Records'!$I:$I,'Leave Records'!$B:$B,$B8,'Leave Records'!$D:$D,Config!$E$11,'Leave Records'!$K:$K,"Pending"))) -> 0 | W8: =IF($B8="","",T8-U8) -> 0 | X8: =IF($B8="","",E8+I8+M8+Q8+U8) -> 3
A9: =IF(B9="","",ROW()-4) -> 5 | B9: =IF(Config!$B$11="","",Config!$B$11) -> Fatema Akter Mili | C9: =IF(Config!$B$11="","",Config!$C$11) | D9: =IF($B9="","",IFERROR(Config!$F$7,0)) -> 10 | E9: =IF($B9="","",IF(Config!$E$7="",0,SUMIFS('Leave Records'!$I:$I,'Leave Records'!$B:$B,$B9,'Leave Records'!$D:$D,Config!$E$7,'Leave Records'!$K:$K,"Approved"))) -> 0 | F9: =IF($B9="","",IF(Config!$E$7="",0,SUMIFS('Leave Records'!$I:$I,'Leave Records'!$B:$B,$B9,'Leave Records'!$D:$D,Config!$E$7,'Leave Records'!$K:$K,"Pending"))) -> 0 | G9: =IF($B9="","",D9-E9) -> 10 | H9: =IF($B9="","",IFERROR(Config!$F$8,0)) -> 5 | I9: =IF($B9="","",IF(Config!$E$8="",0,SUMIFS('Leave Records'!$I:$I,'Leave Records'!$B:$B,$B9,'Leave Records'!$D:$D,Config!$E$8,'Leave Records'!$K:$K,"Approved"))) -> 0 | J9: =IF($B9="","",IF(Config!$E$8="",0,SUMIFS('Leave Records'!$I:$I,'Leave Records'!$B:$B,$B9,'Leave Records'!$D:$D,Config!$E$8,'Leave Records'!$K:$K,"Pending"))) -> 0 | K9: =IF($B9="","",H9-I9) -> 5 | L9: =IF($B9="","",IFERROR(Config!$F$9,0)) -> 0 | M9: =IF($B9="","",IF(Config!$E$9="",0,SUMIFS('Leave Records'!$I:$I,'Leave Records'!$B:$B,$B9,'Leave Records'!$D:$D,Config!$E$9,'Leave Records'!$K:$K,"Approved"))) -> 0 | N9: =IF($B9="","",IF(Config!$E$9="",0,SUMIFS('Leave Records'!$I:$I,'Leave Records'!$B:$B,$B9,'Leave Records'!$D:$D,Config!$E$9,'Leave Records'!$K:$K,"Pending"))) -> 0 | O9: =IF($B9="","",L9-M9) -> 0 | P9: =IF($B9="","",IFERROR(Config!$F$10,0)) -> 0 | Q9: =IF($B9="","",IF(Config!$E$10="",0,SUMIFS('Leave Records'!$I:$I,'Leave Records'!$B:$B,$B9,'Leave Records'!$D:$D,Config!$E$10,'Leave Records'!$K:$K,"Approved"))) -> 0 | R9: =IF($B9="","",IF(Config!$E$10="",0,SUMIFS('Leave Records'!$I:$I,'Leave Records'!$B:$B,$B9,'Leave Records'!$D:$D,Config!$E$10,'Leave Records'!$K:$K,"Pending"))) -> 0 | S9: =IF($B9="","",P9-Q9) -> 0 | T9: =IF($B9="","",IFERROR(Config!$F$11,0)) -> 0 | U9: =IF($B9="","",IF(Config!$E$11="",0,SUMIFS('Leave Records'!$I:$I,'Leave Records'!$B:$B,$B9,'Leave Records'!$D:$D,Config!$E$11,'Leave Records'!$K:$K,"Approved"))) -> 0 | V9: =IF($B9="","",IF(Config!$E$11="",0,SUMIFS('Leave Records'!$I:$I,'Leave Records'!$B:$B,$B9,'Leave Records'!$D:$D,Config!$E$11,'Leave Records'!$K:$K,"Pending"))) -> 0 | W9: =IF($B9="","",T9-U9) -> 0 | X9: =IF($B9="","",E9+I9+M9+Q9+U9) -> 0
A10: =IF(B10="","",ROW()-4) -> 6 | B10: =IF(Config!$B$12="","",Config!$B$12) -> Farida Yesmin Tamanna | C10: =IF(Config!$B$12="","",Config!$C$12) | D10: =IF($B10="","",IFERROR(Config!$F$7,0)) -> 10 | E10: =IF($B10="","",IF(Config!$E$7="",0,SUMIFS('Leave Records'!$I:$I,'Leave Records'!$B:$B,$B10,'Leave Records'!$D:$D,Config!$E$7,'Leave Records'!$K:$K,"Approved"))) -> 2 | F10: =IF($B10="","",IF(Config!$E$7="",0,SUMIFS('Leave Records'!$I:$I,'Leave Records'!$B:$B,$B10,'Leave Records'!$D:$D,Config!$E$7,'Leave Records'!$K:$K,"Pending"))) -> 0 | G10: =IF($B10="","",D10-E10) -> 8 | H10: =IF($B10="","",IFERROR(Config!$F$8,0)) -> 5 | I10: =IF($B10="","",IF(Config!$E$8="",0,SUMIFS('Leave Records'!$I:$I,'Leave Records'!$B:$B,$B10,'Leave Records'!$D:$D,Config!$E$8,'Leave Records'!$K:$K,"Approved"))) -> 0 | J10: =IF($B10="","",IF(Config!$E$8="",0,SUMIFS('Leave Records'!$I:$I,'Leave Records'!$B:$B,$B10,'Leave Records'!$D:$D,Config!$E$8,'Leave Records'!$K:$K,"Pending"))) -> 0 | K10: =IF($B10="","",H10-I10) -> 5 | L10: =IF($B10="","",IFERROR(Config!$F$9,0)) -> 0 | M10: =IF($B10="","",IF(Config!$E$9="",0,SUMIFS('Leave Records'!$I:$I,'Leave Records'!$B:$B,$B10,'Leave Records'!$D:$D,Config!$E$9,'Leave Records'!$K:$K,"Approved"))) -> 0 | N10: =IF($B10="","",IF(Config!$E$9="",0,SUMIFS('Leave Records'!$I:$I,'Leave Records'!$B:$B,$B10,'Leave Records'!$D:$D,Config!$E$9,'Leave Records'!$K:$K,"Pending"))) -> 0 | O10: =IF($B10="","",L10-M10) -> 0 | P10: =IF($B10="","",IFERROR(Config!$F$10,0)) -> 0 | Q10: =IF($B10="","",IF(Config!$E$10="",0,SUMIFS('Leave Records'!$I:$I,'Leave Records'!$B:$B,$B10,'Leave Records'!$D:$D,Config!$E$10,'Leave Records'!$K:$K,"Approved"))) -> 0 | R10: =IF($B10="","",IF(Config!$E$10="",0,SUMIFS('Leave Records'!$I:$I,'Leave Records'!$B:$B,$B10,'Leave Records'!$D:$D,Config!$E$10,'Leave Records'!$K:$K,"Pending"))) -> 0 | S10: =IF($B10="","",P10-Q10) -> 0 | T10: =IF($B10="","",IFERROR(Config!$F$11,0)) -> 0 | U10: =IF($B10="","",IF(Config!$E$11="",0,SUMIFS('Leave Records'!$I:$I,'Leave Records'!$B:$B,$B10,'Leave Records'!$D:$D,Config!$E$11,'Leave Records'!$K:$K,"Approved"))) -> 0 | V10: =IF($B10="","",IF(Config!$E$11="",0,SUMIFS('Leave Records'!$I:$I,'Leave Records'!$B:$B,$B10,'Leave Records'!$D:$D,Config!$E$11,'Leave Records'!$K:$K,"Pending"))) -> 0 | W10: =IF($B10="","",T10-U10) -> 0 | X10: =IF($B10="","",E10+I10+M10+Q10+U10) -> 2
A11: =IF(B11="","",ROW()-4) -> 7 | B11: =IF(Config!$B$13="","",Config!$B$13) -> Shalina Akter Eity | C11: =IF(Config!$B$13="","",Config!$C$13) | D11: =IF($B11="","",IFERROR(Config!$F$7,0)) -> 10 | E11: =IF($B11="","",IF(Config!$E$7="",0,SUMIFS('Leave Records'!$I:$I,'Leave Records'!$B:$B,$B11,'Leave Records'!$D:$D,Config!$E$7,'Leave Records'!$K:$K,"Approved"))) -> 0 | F11: =IF($B11="","",IF(Config!$E$7="",0,SUMIFS('Leave Records'!$I:$I,'Leave Records'!$B:$B,$B11,'Leave Records'!$D:$D,Config!$E$7,'Leave Records'!$K:$K,"Pending"))) -> 0 | G11: =IF($B11="","",D11-E11) -> 10 | H11: =IF($B11="","",IFERROR(Config!$F$8,0)) -> 5 | I11: =IF($B11="","",IF(Config!$E$8="",0,SUMIFS('Leave Records'!$I:$I,'Leave Records'!$B:$B,$B11,'Leave Records'!$D:$D,Config!$E$8,'Leave Records'!$K:$K,"Approved"))) -> 0 | J11: =IF($B11="","",IF(Config!$E$8="",0,SUMIFS('Leave Records'!$I:$I,'Leave Records'!$B:$B,$B11,'Leave Records'!$D:$D,Config!$E$8,'Leave Records'!$K:$K,"Pending"))) -> 0 | K11: =IF($B11="","",H11-I11) -> 5 | L11: =IF($B11="","",IFERROR(Config!$F$9,0)) -> 0 | M11: =IF($B11="","",IF(Config!$E$9="",0,SUMIFS('Leave Records'!$I:$I,'Leave Records'!$B:$B,$B11,'Leave Records'!$D:$D,Config!$E$9,'Leave Records'!$K:$K,"Approved"))) -> 0 | N11: =IF($B11="","",IF(Config!$E$9="",0,SUMIFS('Leave Records'!$I:$I,'Leave Records'!$B:$B,$B11,'Leave Records'!$D:$D,Config!$E$9,'Leave Records'!$K:$K,"Pending"))) -> 0 | O11: =IF($B11="","",L11-M11) -> 0 | P11: =IF($B11="","",IFERROR(Config!$F$10,0)) -> 0 | Q11: =IF($B11="","",IF(Config!$E$10="",0,SUMIFS('Leave Records'!$I:$I,'Leave Records'!$B:$B,$B11,'Leave Records'!$D:$D,Config!$E$10,'Leave Records'!$K:$K,"Approved"))) -> 0 | R11: =IF($B11="","",IF(Config!$E$10="",0,SUMIFS('Leave Records'!$I:$I,'Leave Records'!$B:$B,$B11,'Leave Records'!$D:$D,Config!$E$10,'Leave Records'!$K:$K,"Pending"))) -> 0 | S11: =IF($B11="","",P11-Q11) -> 0 | T11: =IF($B11="","",IFERROR(Config!$F$11,0)) -> 0 | U11: =IF($B11="","",IF(Config!$E$11="",0,SUMIFS('Leave Records'!$I:$I,'Leave Records'!$B:$B,$B11,'Leave Records'!$D:$D,Config!$E$11,'Leave Records'!$K:$K,"Approved"))) -> 0 | V11: =IF($B11="","",IF(Config!$E$11="",0,SUMIFS('Leave Records'!$I:$I,'Leave Records'!$B:$B,$B11,'Leave Records'!$D:$D,Config!$E$11,'Leave Records'!$K:$K,"Pending"))) -> 0 | W11: =IF($B11="","",T11-U11) -> 0 | X11: =IF($B11="","",E11+I11+M11+Q11+U11) -> 0
A12: =IF(B12="","",ROW()-4) -> 8 | B12: =IF(Config!$B$14="","",Config!$B$14) -> Rabia Sultana Prity | C12: =IF(Config!$B$14="","",Config!$C$14) -> Class Teacher | D12: =IF($B12="","",IFERROR(Config!$F$7,0)) -> 10 | E12: =IF($B12="","",IF(Config!$E$7="",0,SUMIFS('Leave Records'!$I:$I,'Leave Records'!$B:$B,$B12,'Leave Records'!$D:$D,Config!$E$7,'Leave Records'!$K:$K,"Approved"))) -> 5 | F12: =IF($B12="","",IF(Config!$E$7="",0,SUMIFS('Leave Records'!$I:$I,'Leave Records'!$B:$B,$B12,'Leave Records'!$D:$D,Config!$E$7,'Leave Records'!$K:$K,"Pending"))) -> 0 | G12: =IF($B12="","",D12-E12) -> 5 | H12: =IF($B12="","",IFERROR(Config!$F$8,0)) -> 5 | I12: =IF($B12="","",IF(Config!$E$8="",0,SUMIFS('Leave Records'!$I:$I,'Leave Records'!$B:$B,$B12,'Leave Records'!$D:$D,Config!$E$8,'Leave Records'!$K:$K,"Approved"))) -> 0 | J12: =IF($B12="","",IF(Config!$E$8="",0,SUMIFS('Leave Records'!$I:$I,'Leave Records'!$B:$B,$B12,'Leave Records'!$D:$D,Config!$E$8,'Leave Records'!$K:$K,"Pending"))) -> 0 | K12: =IF($B12="","",H12-I12) -> 5 | L12: =IF($B12="","",IFERROR(Config!$F$9,0)) -> 0 | M12: =IF($B12="","",IF(Config!$E$9="",0,SUMIFS('Leave Records'!$I:$I,'Leave Records'!$B:$B,$B12,'Leave Records'!$D:$D,Config!$E$9,'Leave Records'!$K:$K,"Approved"))) -> 0 | N12: =IF($B12="","",IF(Config!$E$9="",0,SUMIFS('Leave Records'!$I:$I,'Leave Records'!$B:$B,$B12,'Leave Records'!$D:$D,Config!$E$9,'Leave Records'!$K:$K,"Pending"))) -> 0 | O12: =IF($B12="","",L12-M12) -> 0 | P12: =IF($B12="","",IFERROR(Config!$F$10,0)) -> 0 | Q12: =IF($B12="","",IF(Config!$E$10="",0,SUMIFS('Leave Records'!$I:$I,'Leave Records'!$B:$B,$B12,'Leave Records'!$D:$D,Config!$E$10,'Leave Records'!$K:$K,"Approved"))) -> 0 | R12: =IF($B12="","",IF(Config!$E$10="",0,SUMIFS('Leave Records'!$I:$I,'Leave Records'!$B:$B,$B12,'Leave Records'!$D:$D,Config!$E$10,'Leave Records'!$K:$K,"Pending"))) -> 0 | S12: =IF($B12="","",P12-Q12) -> 0 | T12: =IF($B12="","",IFERROR(Config!$F$11,0)) -> 0 | U12: =IF($B12="","",IF(Config!$E$11="",0,SUMIFS('Leave Records'!$I:$I,'Leave Records'!$B:$B,$B12,'Leave Records'!$D:$D,Config!$E$11,'Leave Records'!$K:$K,"Approved"))) -> 0 | V12: =IF($B12="","",IF(Config!$E$11="",0,SUMIFS('Leave Records'!$I:$I,'Leave Records'!$B:$B,$B12,'Leave Records'!$D:$D,Config!$E$11,'Leave Records'!$K:$K,"Pending"))) -> 0 | W12: =IF($B12="","",T12-U12) -> 0 | X12: =IF($B12="","",E12+I12+M12+Q12+U12) -> 5
A13: =IF(B13="","",ROW()-4) -> 9 | B13: =IF(Config!$B$15="","",Config!$B$15) -> Afrin Jahan Uzma | C13: =IF(Config!$B$15="","",Config!$C$15) -> Lead Teacher | D13: =IF($B13="","",IFERROR(Config!$F$7,0)) -> 10 | E13: =IF($B13="","",IF(Config!$E$7="",0,SUMIFS('Leave Records'!$I:$I,'Leave Records'!$B:$B,$B13,'Leave Records'!$D:$D,Config!$E$7,'Leave Records'!$K:$K,"Approved"))) -> 5 | F13: =IF($B13="","",IF(Config!$E$7="",0,SUMIFS('Leave Records'!$I:$I,'Leave Records'!$B:$B,$B13,'Leave Records'!$D:$D,Config!$E$7,'Leave Records'!$K:$K,"Pending"))) -> 0 | G13: =IF($B13="","",D13-E13) -> 5 | H13: =IF($B13="","",IFERROR(Config!$F$8,0)) -> 5 | I13: =IF($B13="","",IF(Config!$E$8="",0,SUMIFS('Leave Records'!$I:$I,'Leave Records'!$B:$B,$B13,'Leave Records'!$D:$D,Config!$E$8,'Leave Records'!$K:$K,"Approved"))) -> 0 | J13: =IF($B13="","",IF(Config!$E$8="",0,SUMIFS('Leave Records'!$I:$I,'Leave Records'!$B:$B,$B13,'Leave Records'!$D:$D,Config!$E$8,'Leave Records'!$K:$K,"Pending"))) -> 0 | K13: =IF($B13="","",H13-I13) -> 5 | L13: =IF($B13="","",IFERROR(Config!$F$9,0)) -> 0 | M13: =IF($B13="","",IF(Config!$E$9="",0,SUMIFS('Leave Records'!$I:$I,'Leave Records'!$B:$B,$B13,'Leave Records'!$D:$D,Config!$E$9,'Leave Records'!$K:$K,"Approved"))) -> 0 | N13: =IF($B13="","",IF(Config!$E$9="",0,SUMIFS('Leave Records'!$I:$I,'Leave Records'!$B:$B,$B13,'Leave Records'!$D:$D,Config!$E$9,'Leave Records'!$K:$K,"Pending"))) -> 0 | O13: =IF($B13="","",L13-M13) -> 0 | P13: =IF($B13="","",IFERROR(Config!$F$10,0)) -> 0 | Q13: =IF($B13="","",IF(Config!$E$10="",0,SUMIFS('Leave Records'!$I:$I,'Leave Records'!$B:$B,$B13,'Leave Records'!$D:$D,Config!$E$10,'Leave Records'!$K:$K,"Approved"))) -> 0 | R13: =IF($B13="","",IF(Config!$E$10="",0,SUMIFS('Leave Records'!$I:$I,'Leave Records'!$B:$B,$B13,'Leave Records'!$D:$D,Config!$E$10,'Leave Records'!$K:$K,"Pending"))) -> 0 | S13: =IF($B13="","",P13-Q13) -> 0 | T13: =IF($B13="","",IFERROR(Config!$F$11,0)) -> 0 | U13: =IF($B13="","",IF(Config!$E$11="",0,SUMIFS('Leave Records'!$I:$I,'Leave Records'!$B:$B,$B13,'Leave Records'!$D:$D,Config!$E$11,'Leave Records'!$K:$K,"Approved"))) -> 0 | V13: =IF($B13="","",IF(Config!$E$11="",0,SUMIFS('Leave Records'!$I:$I,'Leave Records'!$B:$B,$B13,'Leave Records'!$D:$D,Config!$E$11,'Leave Records'!$K:$K,"Pending"))) -> 0 | W13: =IF($B13="","",T13-U13) -> 0 | X13: =IF($B13="","",E13+I13+M13+Q13+U13) -> 5
A14: =IF(B14="","",ROW()-4) -> 10 | B14: =IF(Config!$B$16="","",Config!$B$16) -> Ariful Islam Maruf | C14: =IF(Config!$B$16="","",Config!$C$16) | D14: =IF($B14="","",IFERROR(Config!$F$7,0)) -> 10 | E14: =IF($B14="","",IF(Config!$E$7="",0,SUMIFS('Leave Records'!$I:$I,'Leave Records'!$B:$B,$B14,'Leave Records'!$D:$D,Config!$E$7,'Leave Records'!$K:$K,"Approved"))) -> 2 | F14: =IF($B14="","",IF(Config!$E$7="",0,SUMIFS('Leave Records'!$I:$I,'Leave Records'!$B:$B,$B14,'Leave Records'!$D:$D,Config!$E$7,'Leave Records'!$K:$K,"Pending"))) -> 0 | G14: =IF($B14="","",D14-E14) -> 8 | H14: =IF($B14="","",IFERROR(Config!$F$8,0)) -> 5 | I14: =IF($B14="","",IF(Config!$E$8="",0,SUMIFS('Leave Records'!$I:$I,'Leave Records'!$B:$B,$B14,'Leave Records'!$D:$D,Config!$E$8,'Leave Records'!$K:$K,"Approved"))) -> 0 | J14: =IF($B14="","",IF(Config!$E$8="",0,SUMIFS('Leave Records'!$I:$I,'Leave Records'!$B:$B,$B14,'Leave Records'!$D:$D,Config!$E$8,'Leave Records'!$K:$K,"Pending"))) -> 0 | K14: =IF($B14="","",H14-I14) -> 5 | L14: =IF($B14="","",IFERROR(Config!$F$9,0)) -> 0 | M14: =IF($B14="","",IF(Config!$E$9="",0,SUMIFS('Leave Records'!$I:$I,'Leave Records'!$B:$B,$B14,'Leave Records'!$D:$D,Config!$E$9,'Leave Records'!$K:$K,"Approved"))) -> 0 | N14: =IF($B14="","",IF(Config!$E$9="",0,SUMIFS('Leave Records'!$I:$I,'Leave Records'!$B:$B,$B14,'Leave Records'!$D:$D,Config!$E$9,'Leave Records'!$K:$K,"Pending"))) -> 0 | O14: =IF($B14="","",L14-M14) -> 0 | P14: =IF($B14="","",IFERROR(Config!$F$10,0)) -> 0 | Q14: =IF($B14="","",IF(Config!$E$10="",0,SUMIFS('Leave Records'!$I:$I,'Leave Records'!$B:$B,$B14,'Leave Records'!$D:$D,Config!$E$10,'Leave Records'!$K:$K,"Approved"))) -> 0 | R14: =IF($B14="","",IF(Config!$E$10="",0,SUMIFS('Leave Records'!$I:$I,'Leave Records'!$B:$B,$B14,'Leave Records'!$D:$D,Config!$E$10,'Leave Records'!$K:$K,"Pending"))) -> 0 | S14: =IF($B14="","",P14-Q14) -> 0 | T14: =IF($B14="","",IFERROR(Config!$F$11,0)) -> 0 | U14: =IF($B14="","",IF(Config!$E$11="",0,SUMIFS('Leave Records'!$I:$I,'Leave Records'!$B:$B,$B14,'Leave Records'!$D:$D,Config!$E$11,'Leave Records'!$K:$K,"Approved"))) -> 0 | V14: =IF($B14="","",IF(Config!$E$11="",0,SUMIFS('Leave Records'!$I:$I,'Leave Records'!$B:$B,$B14,'Leave Records'!$D:$D,Config!$E$11,'Leave Records'!$K:$K,"Pending"))) -> 0 | W14: =IF($B14="","",T14-U14) -> 0 | X14: =IF($B14="","",E14+I14+M14+Q14+U14) -> 2
A15: =IF(B15="","",ROW()-4) -> 11 | B15: =IF(Config!$B$17="","",Config!$B$17) -> Jinat Farhana Chy | C15: =IF(Config!$B$17="","",Config!$C$17) -> Asst. Co-ord. (Pre-School) | D15: =IF($B15="","",IFERROR(Config!$F$7,0)) -> 10 | E15: =IF($B15="","",IF(Config!$E$7="",0,SUMIFS('Leave Records'!$I:$I,'Leave Records'!$B:$B,$B15,'Leave Records'!$D:$D,Config!$E$7,'Leave Records'!$K:$K,"Approved"))) -> 6 | F15: =IF($B15="","",IF(Config!$E$7="",0,SUMIFS('Leave Records'!$I:$I,'Leave Records'!$B:$B,$B15,'Leave Records'!$D:$D,Config!$E$7,'Leave Records'!$K:$K,"Pending"))) -> 0 | G15: =IF($B15="","",D15-E15) -> 4 | H15: =IF($B15="","",IFERROR(Config!$F$8,0)) -> 5 | I15: =IF($B15="","",IF(Config!$E$8="",0,SUMIFS('Leave Records'!$I:$I,'Leave Records'!$B:$B,$B15,'Leave Records'!$D:$D,Config!$E$8,'Leave Records'!$K:$K,"Approved"))) -> 0 | J15: =IF($B15="","",IF(Config!$E$8="",0,SUMIFS('Leave Records'!$I:$I,'Leave Records'!$B:$B,$B15,'Leave Records'!$D:$D,Config!$E$8,'Leave Records'!$K:$K,"Pending"))) -> 0 | K15: =IF($B15="","",H15-I15) -> 5 | L15: =IF($B15="","",IFERROR(Config!$F$9,0)) -> 0 | M15: =IF($B15="","",IF(Config!$E$9="",0,SUMIFS('Leave Records'!$I:$I,'Leave Records'!$B:$B,$B15,'Leave Records'!$D:$D,Config!$E$9,'Leave Records'!$K:$K,"Approved"))) -> 0 | N15: =IF($B15="","",IF(Config!$E$9="",0,SUMIFS('Leave Records'!$I:$I,'Leave Records'!$B:$B,$B15,'Leave Records'!$D:$D,Config!$E$9,'Leave Records'!$K:$K,"Pending"))) -> 0 | O15: =IF($B15="","",L15-M15) -> 0 | P15: =IF($B15="","",IFERROR(Config!$F$10,0)) -> 0 | Q15: =IF($B15="","",IF(Config!$E$10="",0,SUMIFS('Leave Records'!$I:$I,'Leave Records'!$B:$B,$B15,'Leave Records'!$D:$D,Config!$E$10,'Leave Records'!$K:$K,"Approved"))) -> 0 | R15: =IF($B15="","",IF(Config!$E$10="",0,SUMIFS('Leave Records'!$I:$I,'Leave Records'!$B:$B,$B15,'Leave Records'!$D:$D,Config!$E$10,'Leave Records'!$K:$K,"Pending"))) -> 0 | S15: =IF($B15="","",P15-Q15) -> 0 | T15: =IF($B15="","",IFERROR(Config!$F$11,0)) -> 0 | U15: =IF($B15="","",IF(Config!$E$11="",0,SUMIFS('Leave Records'!$I:$I,'Leave Records'!$B:$B,$B15,'Leave Records'!$D:$D,Config!$E$11,'Leave Records'!$K:$K,"Approved"))) -> 0 | V15: =IF($B15="","",IF(Config!$E$11="",0,SUMIFS('Leave Records'!$I:$I,'Leave Records'!$B:$B,$B15,'Leave Records'!$D:$D,Config!$E$11,'Leave Records'!$K:$K,"Pending"))) -> 0 | W15: =IF($B15="","",T15-U15) -> 0 | X15: =IF($B15="","",E15+I15+M15+Q15+U15) -> 6
A16: =IF(B16="","",ROW()-4) -> 12 | B16: =IF(Config!$B$18="","",Config!$B$18) -> Tabassuma Barat Chowdhury | C16: =IF(Config!$B$18="","",Config!$C$18) -> Primary Co-ordinator | D16: =IF($B16="","",IFERROR(Config!$F$7,0)) -> 10 | E16: =IF($B16="","",IF(Config!$E$7="",0,SUMIFS('Leave Records'!$I:$I,'Leave Records'!$B:$B,$B16,'Leave Records'!$D:$D,Config!$E$7,'Leave Records'!$K:$K,"Approved"))) -> 0 | F16: =IF($B16="","",IF(Config!$E$7="",0,SUMIFS('Leave Records'!$I:$I,'Leave Records'!$B:$B,$B16,'Leave Records'!$D:$D,Config!$E$7,'Leave Records'!$K:$K,"Pending"))) -> 0 | G16: =IF($B16="","",D16-E16) -> 10 | H16: =IF($B16="","",IFERROR(Config!$F$8,0)) -> 5 | I16: =IF($B16="","",IF(Config!$E$8="",0,SUMIFS('Leave Records'!$I:$I,'Leave Records'!$B:$B,$B16,'Leave Records'!$D:$D,Config!$E$8,'Leave Records'!$K:$K,"Approved"))) -> 1 | J16: =IF($B16="","",IF(Config!$E$8="",0,SUMIFS('Leave Records'!$I:$I,'Leave Records'!$B:$B,$B16,'Leave Records'!$D:$D,Config!$E$8,'Leave Records'!$K:$K,"Pending"))) -> 0 | K16: =IF($B16="","",H16-I16) -> 4 | L16: =IF($B16="","",IFERROR(Config!$F$9,0)) -> 0 | M16: =IF($B16="","",IF(Config!$E$9="",0,SUMIFS('Leave Records'!$I:$I,'Leave Records'!$B:$B,$B16,'Leave Records'!$D:$D,Config!$E$9,'Leave Records'!$K:$K,"Approved"))) -> 0 | N16: =IF($B16="","",IF(Config!$E$9="",0,SUMIFS('Leave Records'!$I:$I,'Leave Records'!$B:$B,$B16,'Leave Records'!$D:$D,Config!$E$9,'Leave Records'!$K:$K,"Pending"))) -> 0 | O16: =IF($B16="","",L16-M16) -> 0 | P16: =IF($B16="","",IFERROR(Config!$F$10,0)) -> 0 | Q16: =IF($B16="","",IF(Config!$E$10="",0,SUMIFS('Leave Records'!$I:$I,'Leave Records'!$B:$B,$B16,'Leave Records'!$D:$D,Config!$E$10,'Leave Records'!$K:$K,"Approved"))) -> 0 | R16: =IF($B16="","",IF(Config!$E$10="",0,SUMIFS('Leave Records'!$I:$I,'Leave Records'!$B:$B,$B16,'Leave Records'!$D:$D,Config!$E$10,'Leave Records'!$K:$K,"Pending"))) -> 0 | S16: =IF($B16="","",P16-Q16) -> 0 | T16: =IF($B16="","",IFERROR(Config!$F$11,0)) -> 0 | U16: =IF($B16="","",IF(Config!$E$11="",0,SUMIFS('Leave Records'!$I:$I,'Leave Records'!$B:$B,$B16,'Leave Records'!$D:$D,Config!$E$11,'Leave Records'!$K:$K,"Approved"))) -> 0 | V16: =IF($B16="","",IF(Config!$E$11="",0,SUMIFS('Leave Records'!$I:$I,'Leave Records'!$B:$B,$B16,'Leave Records'!$D:$D,Config!$E$11,'Leave Records'!$K:$K,"Pending"))) -> 0 | W16: =IF($B16="","",T16-U16) -> 0 | X16: =IF($B16="","",E16+I16+M16+Q16+U16) -> 1
A17: =IF(B17="","",ROW()-4) -> 13 | B17: =IF(Config!$B$19="","",Config!$B$19) -> Sumaya Rahman | C17: =IF(Config!$B$19="","",Config!$C$19) -> Asst. Co-ord. (Secondary) | D17: =IF($B17="","",IFERROR(Config!$F$7,0)) -> 10 | E17: =IF($B17="","",IF(Config!$E$7="",0,SUMIFS('Leave Records'!$I:$I,'Leave Records'!$B:$B,$B17,'Leave Records'!$D:$D,Config!$E$7,'Leave Records'!$K:$K,"Approved"))) -> 3 | F17: =IF($B17="","",IF(Config!$E$7="",0,SUMIFS('Leave Records'!$I:$I,'Leave Records'!$B:$B,$B17,'Leave Records'!$D:$D,Config!$E$7,'Leave Records'!$K:$K,"Pending"))) -> 0 | G17: =IF($B17="","",D17-E17) -> 7 | H17: =IF($B17="","",IFERROR(Config!$F$8,0)) -> 5 | I17: =IF($B17="","",IF(Config!$E$8="",0,SUMIFS('Leave Records'!$I:$I,'Leave Records'!$B:$B,$B17,'Leave Records'!$D:$D,Config!$E$8,'Leave Records'!$K:$K,"Approved"))) -> 0 | J17: =IF($B17="","",IF(Config!$E$8="",0,SUMIFS('Leave Records'!$I:$I,'Leave Records'!$B:$B,$B17,'Leave Records'!$D:$D,Config!$E$8,'Leave Records'!$K:$K,"Pending"))) -> 0 | K17: =IF($B17="","",H17-I17) -> 5 | L17: =IF($B17="","",IFERROR(Config!$F$9,0)) -> 0 | M17: =IF($B17="","",IF(Config!$E$9="",0,SUMIFS('Leave Records'!$I:$I,'Leave Records'!$B:$B,$B17,'Leave Records'!$D:$D,Config!$E$9,'Leave Records'!$K:$K,"Approved"))) -> 0 | N17: =IF($B17="","",IF(Config!$E$9="",0,SUMIFS('Leave Records'!$I:$I,'Leave Records'!$B:$B,$B17,'Leave Records'!$D:$D,Config!$E$9,'Leave Records'!$K:$K,"Pending"))) -> 0 | O17: =IF($B17="","",L17-M17) -> 0 | P17: =IF($B17="","",IFERROR(Config!$F$10,0)) -> 0 | Q17: =IF($B17="","",IF(Config!$E$10="",0,SUMIFS('Leave Records'!$I:$I,'Leave Records'!$B:$B,$B17,'Leave Records'!$D:$D,Config!$E$10,'Leave Records'!$K:$K,"Approved"))) -> 0 | R17: =IF($B17="","",IF(Config!$E$10="",0,SUMIFS('Leave Records'!$I:$I,'Leave Records'!$B:$B,$B17,'Leave Records'!$D:$D,Config!$E$10,'Leave Records'!$K:$K,"Pending"))) -> 0 | S17: =IF($B17="","",P17-Q17) -> 0 | T17: =IF($B17="","",IFERROR(Config!$F$11,0)) -> 0 | U17: =IF($B17="","",IF(Config!$E$11="",0,SUMIFS('Leave Records'!$I:$I,'Leave Records'!$B:$B,$B17,'Leave Records'!$D:$D,Config!$E$11,'Leave Records'!$K:$K,"Approved"))) -> 0 | V17: =IF($B17="","",IF(Config!$E$11="",0,SUMIFS('Leave Records'!$I:$I,'Leave Records'!$B:$B,$B17,'Leave Records'!$D:$D,Config!$E$11,'Leave Records'!$K:$K,"Pending"))) -> 0 | W17: =IF($B17="","",T17-U17) -> 0 | X17: =IF($B17="","",E17+I17+M17+Q17+U17) -> 3
A18: =IF(B18="","",ROW()-4) -> 14 | B18: =IF(Config!$B$20="","",Config!$B$20) -> Warda Siraj | C18: =IF(Config!$B$20="","",Config!$C$20) -> Head Of BC | D18: =IF($B18="","",IFERROR(Config!$F$7,0)) -> 10 | E18: =IF($B18="","",IF(Config!$E$7="",0,SUMIFS('Leave Records'!$I:$I,'Leave Records'!$B:$B,$B18,'Leave Records'!$D:$D,Config!$E$7,'Leave Records'!$K:$K,"Approved"))) -> 1 | F18: =IF($B18="","",IF(Config!$E$7="",0,SUMIFS('Leave Records'!$I:$I,'Leave Records'!$B:$B,$B18,'Leave Records'!$D:$D,Config!$E$7,'Leave Records'!$K:$K,"Pending"))) -> 0 | G18: =IF($B18="","",D18-E18) -> 9 | H18: =IF($B18="","",IFERROR(Config!$F$8,0)) -> 5 | I18: =IF($B18="","",IF(Config!$E$8="",0,SUMIFS('Leave Records'!$I:$I,'Leave Records'!$B:$B,$B18,'Leave Records'!$D:$D,Config!$E$8,'Leave Records'!$K:$K,"Approved"))) -> 1 | J18: =IF($B18="","",IF(Config!$E$8="",0,SUMIFS('Leave Records'!$I:$I,'Leave Records'!$B:$B,$B18,'Leave Records'!$D:$D,Config!$E$8,'Leave Records'!$K:$K,"Pending"))) -> 0 | K18: =IF($B18="","",H18-I18) -> 4 | L18: =IF($B18="","",IFERROR(Config!$F$9,0)) -> 0 | M18: =IF($B18="","",IF(Config!$E$9="",0,SUMIFS('Leave Records'!$I:$I,'Leave Records'!$B:$B,$B18,'Leave Records'!$D:$D,Config!$E$9,'Leave Records'!$K:$K,"Approved"))) -> 0 | N18: =IF($B18="","",IF(Config!$E$9="",0,SUMIFS('Leave Records'!$I:$I,'Leave Records'!$B:$B,$B18,'Leave Records'!$D:$D,Config!$E$9,'Leave Records'!$K:$K,"Pending"))) -> 0 | O18: =IF($B18="","",L18-M18) -> 0 | P18: =IF($B18="","",IFERROR(Config!$F$10,0)) -> 0 | Q18: =IF($B18="","",IF(Config!$E$10="",0,SUMIFS('Leave Records'!$I:$I,'Leave Records'!$B:$B,$B18,'Leave Records'!$D:$D,Config!$E$10,'Leave Records'!$K:$K,"Approved"))) -> 0 | R18: =IF($B18="","",IF(Config!$E$10="",0,SUMIFS('Leave Records'!$I:$I,'Leave Records'!$B:$B,$B18,'Leave Records'!$D:$D,Config!$E$10,'Leave Records'!$K:$K,"Pending"))) -> 0 | S18: =IF($B18="","",P18-Q18) -> 0 | T18: =IF($B18="","",IFERROR(Config!$F$11,0)) -> 0 | U18: =IF($B18="","",IF(Config!$E$11="",0,SUMIFS('Leave Records'!$I:$I,'Leave Records'!$B:$B,$B18,'Leave Records'!$D:$D,Config!$E$11,'Leave Records'!$K:$K,"Approved"))) -> 0 | V18: =IF($B18="","",IF(Config!$E$11="",0,SUMIFS('Leave Records'!$I:$I,'Leave Records'!$B:$B,$B18,'Leave Records'!$D:$D,Config!$E$11,'Leave Records'!$K:$K,"Pending"))) -> 0 | W18: =IF($B18="","",T18-U18) -> 0 | X18: =IF($B18="","",E18+I18+M18+Q18+U18) -> 2
A19: =IF(B19="","",ROW()-4) -> 15 | B19: =IF(Config!$B$21="","",Config!$B$21) -> Irfan Hossain | C19: =IF(Config!$B$21="","",Config!$C$21) | D19: =IF($B19="","",IFERROR(Config!$F$7,0)) -> 10 | E19: =IF($B19="","",IF(Config!$E$7="",0,SUMIFS('Leave Records'!$I:$I,'Leave Records'!$B:$B,$B19,'Leave Records'!$D:$D,Config!$E$7,'Leave Records'!$K:$K,"Approved"))) -> 4 | F19: =IF($B19="","",IF(Config!$E$7="",0,SUMIFS('Leave Records'!$I:$I,'Leave Records'!$B:$B,$B19,'Leave Records'!$D:$D,Config!$E$7,'Leave Records'!$K:$K,"Pending"))) -> 0 | G19: =IF($B19="","",D19-E19) -> 6 | H19: =IF($B19="","",IFERROR(Config!$F$8,0)) -> 5 | I19: =IF($B19="","",IF(Config!$E$8="",0,SUMIFS('Leave Records'!$I:$I,'Leave Records'!$B:$B,$B19,'Leave Records'!$D:$D,Config!$E$8,'Leave Records'!$K:$K,"Approved"))) -> 0 | J19: =IF($B19="","",IF(Config!$E$8="",0,SUMIFS('Leave Records'!$I:$I,'Leave Records'!$B:$B,$B19,'Leave Records'!$D:$D,Config!$E$8,'Leave Records'!$K:$K,"Pending"))) -> 0 | K19: =IF($B19="","",H19-I19) -> 5 | L19: =IF($B19="","",IFERROR(Config!$F$9,0)) -> 0 | M19: =IF($B19="","",IF(Config!$E$9="",0,SUMIFS('Leave Records'!$I:$I,'Leave Records'!$B:$B,$B19,'Leave Records'!$D:$D,Config!$E$9,'Leave Records'!$K:$K,"Approved"))) -> 0 | N19: =IF($B19="","",IF(Config!$E$9="",0,SUMIFS('Leave Records'!$I:$I,'Leave Records'!$B:$B,$B19,'Leave Records'!$D:$D,Config!$E$9,'Leave Records'!$K:$K,"Pending"))) -> 0 | O19: =IF($B19="","",L19-M19) -> 0 | P19: =IF($B19="","",IFERROR(Config!$F$10,0)) -> 0 | Q19: =IF($B19="","",IF(Config!$E$10="",0,SUMIFS('Leave Records'!$I:$I,'Leave Records'!$B:$B,$B19,'Leave Records'!$D:$D,Config!$E$10,'Leave Records'!$K:$K,"Approved"))) -> 0 | R19: =IF($B19="","",IF(Config!$E$10="",0,SUMIFS('Leave Records'!$I:$I,'Leave Records'!$B:$B,$B19,'Leave Records'!$D:$D,Config!$E$10,'Leave Records'!$K:$K,"Pending"))) -> 0 | S19: =IF($B19="","",P19-Q19) -> 0 | T19: =IF($B19="","",IFERROR(Config!$F$11,0)) -> 0 | U19: =IF($B19="","",IF(Config!$E$11="",0,SUMIFS('Leave Records'!$I:$I,'Leave Records'!$B:$B,$B19,'Leave Records'!$D:$D,Config!$E$11,'Leave Records'!$K:$K,"Approved"))) -> 0 | V19: =IF($B19="","",IF(Config!$E$11="",0,SUMIFS('Leave Records'!$I:$I,'Leave Records'!$B:$B,$B19,'Leave Records'!$D:$D,Config!$E$11,'Leave Records'!$K:$K,"Pending"))) -> 0 | W19: =IF($B19="","",T19-U19) -> 0 | X19: =IF($B19="","",E19+I19+M19+Q19+U19) -> 4
A20: =IF(B20="","",ROW()-4) -> 16 | B20: =IF(Config!$B$22="","",Config!$B$22) -> Mohoshina Shifa Buble | C20: =IF(Config!$B$22="","",Config!$C$22) -> Teacher's Assistant | D20: =IF($B20="","",IFERROR(Config!$F$7,0)) -> 10 | E20: =IF($B20="","",IF(Config!$E$7="",0,SUMIFS('Leave Records'!$I:$I,'Leave Records'!$B:$B,$B20,'Leave Records'!$D:$D,Config!$E$7,'Leave Records'!$K:$K,"Approved"))) -> 6 | F20: =IF($B20="","",IF(Config!$E$7="",0,SUMIFS('Leave Records'!$I:$I,'Leave Records'!$B:$B,$B20,'Leave Records'!$D:$D,Config!$E$7,'Leave Records'!$K:$K,"Pending"))) -> 0 | G20: =IF($B20="","",D20-E20) -> 4 | H20: =IF($B20="","",IFERROR(Config!$F$8,0)) -> 5 | I20: =IF($B20="","",IF(Config!$E$8="",0,SUMIFS('Leave Records'!$I:$I,'Leave Records'!$B:$B,$B20,'Leave Records'!$D:$D,Config!$E$8,'Leave Records'!$K:$K,"Approved"))) -> 0 | J20: =IF($B20="","",IF(Config!$E$8="",0,SUMIFS('Leave Records'!$I:$I,'Leave Records'!$B:$B,$B20,'Leave Records'!$D:$D,Config!$E$8,'Leave Records'!$K:$K,"Pending"))) -> 0 | K20: =IF($B20="","",H20-I20) -> 5 | L20: =IF($B20="","",IFERROR(Config!$F$9,0)) -> 0 | M20: =IF($B20="","",IF(Config!$E$9="",0,SUMIFS('Leave Records'!$I:$I,'Leave Records'!$B:$B,$B20,'Leave Records'!$D:$D,Config!$E$9,'Leave Records'!$K:$K,"Approved"))) -> 0 | N20: =IF($B20="","",IF(Config!$E$9="",0,SUMIFS('Leave Records'!$I:$I,'Leave Records'!$B:$B,$B20,'Leave Records'!$D:$D,Config!$E$9,'Leave Records'!$K:$K,"Pending"))) -> 0 | O20: =IF($B20="","",L20-M20) -> 0 | P20: =IF($B20="","",IFERROR(Config!$F$10,0)) -> 0 | Q20: =IF($B20="","",IF(Config!$E$10="",0,SUMIFS('Leave Records'!$I:$I,'Leave Records'!$B:$B,$B20,'Leave Records'!$D:$D,Config!$E$10,'Leave Records'!$K:$K,"Approved"))) -> 0 | R20: =IF($B20="","",IF(Config!$E$10="",0,SUMIFS('Leave Records'!$I:$I,'Leave Records'!$B:$B,$B20,'Leave Records'!$D:$D,Config!$E$10,'Leave Records'!$K:$K,"Pending"))) -> 0 | S20: =IF($B20="","",P20-Q20) -> 0 | T20: =IF($B20="","",IFERROR(Config!$F$11,0)) -> 0 | U20: =IF($B20="","",IF(Config!$E$11="",0,SUMIFS('Leave Records'!$I:$I,'Leave Records'!$B:$B,$B20,'Leave Records'!$D:$D,Config!$E$11,'Leave Records'!$K:$K,"Approved"))) -> 0 | V20: =IF($B20="","",IF(Config!$E$11="",0,SUMIFS('Leave Records'!$I:$I,'Leave Records'!$B:$B,$B20,'Leave Records'!$D:$D,Config!$E$11,'Leave Records'!$K:$K,"Pending"))) -> 0 | W20: =IF($B20="","",T20-U20) -> 0 | X20: =IF($B20="","",E20+I20+M20+Q20+U20) -> 6
A21: =IF(B21="","",ROW()-4) -> 17 | B21: =IF(Config!$B$23="","",Config!$B$23) -> Sadia Akter Lubna | C21: =IF(Config!$B$23="","",Config!$C$23) -> Teacher's Assistant | D21: =IF($B21="","",IFERROR(Config!$F$7,0)) -> 10 | E21: =IF($B21="","",IF(Config!$E$7="",0,SUMIFS('Leave Records'!$I:$I,'Leave Records'!$B:$B,$B21,'Leave Records'!$D:$D,Config!$E$7,'Leave Records'!$K:$K,"Approved"))) -> 4 | F21: =IF($B21="","",IF(Config!$E$7="",0,SUMIFS('Leave Records'!$I:$I,'Leave Records'!$B:$B,$B21,'Leave Records'!$D:$D,Config!$E$7,'Leave Records'!$K:$K,"Pending"))) -> 0 | G21: =IF($B21="","",D21-E21) -> 6 | H21: =IF($B21="","",IFERROR(Config!$F$8,0)) -> 5 | I21: =IF($B21="","",IF(Config!$E$8="",0,SUMIFS('Leave Records'!$I:$I,'Leave Records'!$B:$B,$B21,'Leave Records'!$D:$D,Config!$E$8,'Leave Records'!$K:$K,"Approved"))) -> 0 | J21: =IF($B21="","",IF(Config!$E$8="",0,SUMIFS('Leave Records'!$I:$I,'Leave Records'!$B:$B,$B21,'Leave Records'!$D:$D,Config!$E$8,'Leave Records'!$K:$K,"Pending"))) -> 0 | K21: =IF($B21="","",H21-I21) -> 5 | L21: =IF($B21="","",IFERROR(Config!$F$9,0)) -> 0 | M21: =IF($B21="","",IF(Config!$E$9="",0,SUMIFS('Leave Records'!$I:$I,'Leave Records'!$B:$B,$B21,'Leave Records'!$D:$D,Config!$E$9,'Leave Records'!$K:$K,"Approved"))) -> 0 | N21: =IF($B21="","",IF(Config!$E$9="",0,SUMIFS('Leave Records'!$I:$I,'Leave Records'!$B:$B,$B21,'Leave Records'!$D:$D,Config!$E$9,'Leave Records'!$K:$K,"Pending"))) -> 0 | O21: =IF($B21="","",L21-M21) -> 0 | P21: =IF($B21="","",IFERROR(Config!$F$10,0)) -> 0 | Q21: =IF($B21="","",IF(Config!$E$10="",0,SUMIFS('Leave Records'!$I:$I,'Leave Records'!$B:$B,$B21,'Leave Records'!$D:$D,Config!$E$10,'Leave Records'!$K:$K,"Approved"))) -> 0 | R21: =IF($B21="","",IF(Config!$E$10="",0,SUMIFS('Leave Records'!$I:$I,'Leave Records'!$B:$B,$B21,'Leave Records'!$D:$D,Config!$E$10,'Leave Records'!$K:$K,"Pending"))) -> 0 | S21: =IF($B21="","",P21-Q21) -> 0 | T21: =IF($B21="","",IFERROR(Config!$F$11,0)) -> 0 | U21: =IF($B21="","",IF(Config!$E$11="",0,SUMIFS('Leave Records'!$I:$I,'Leave Records'!$B:$B,$B21,'Leave Records'!$D:$D,Config!$E$11,'Leave Records'!$K:$K,"Approved"))) -> 0 | V21: =IF($B21="","",IF(Config!$E$11="",0,SUMIFS('Leave Records'!$I:$I,'Leave Records'!$B:$B,$B21,'Leave Records'!$D:$D,Config!$E$11,'Leave Records'!$K:$K,"Pending"))) -> 0 | W21: =IF($B21="","",T21-U21) -> 0 | X21: =IF($B21="","",E21+I21+M21+Q21+U21) -> 4
A22: =IF(B22="","",ROW()-4) -> 18 | B22: =IF(Config!$B$24="","",Config!$B$24) -> Taslima Akter | C22: =IF(Config!$B$24="","",Config!$C$24) -> Subject Teacher (IC) | D22: =IF($B22="","",IFERROR(Config!$F$7,0)) -> 10 | E22: =IF($B22="","",IF(Config!$E$7="",0,SUMIFS('Leave Records'!$I:$I,'Leave Records'!$B:$B,$B22,'Leave Records'!$D:$D,Config!$E$7,'Leave Records'!$K:$K,"Approved"))) -> 7 | F22: =IF($B22="","",IF(Config!$E$7="",0,SUMIFS('Leave Records'!$I:$I,'Leave Records'!$B:$B,$B22,'Leave Records'!$D:$D,Config!$E$7,'Leave Records'!$K:$K,"Pending"))) -> 0 | G22: =IF($B22="","",D22-E22) -> 3 | H22: =IF($B22="","",IFERROR(Config!$F$8,0)) -> 5 | I22: =IF($B22="","",IF(Config!$E$8="",0,SUMIFS('Leave Records'!$I:$I,'Leave Records'!$B:$B,$B22,'Leave Records'!$D:$D,Config!$E$8,'Leave Records'!$K:$K,"Approved"))) -> 0 | J22: =IF($B22="","",IF(Config!$E$8="",0,SUMIFS('Leave Records'!$I:$I,'Leave Records'!$B:$B,$B22,'Leave Records'!$D:$D,Config!$E$8,'Leave Records'!$K:$K,"Pending"))) -> 0 | K22: =IF($B22="","",H22-I22) -> 5 | L22: =IF($B22="","",IFERROR(Config!$F$9,0)) -> 0 | M22: =IF($B22="","",IF(Config!$E$9="",0,SUMIFS('Leave Records'!$I:$I,'Leave Records'!$B:$B,$B22,'Leave Records'!$D:$D,Config!$E$9,'Leave Records'!$K:$K,"Approved"))) -> 0 | N22: =IF($B22="","",IF(Config!$E$9="",0,SUMIFS('Leave Records'!$I:$I,'Leave Records'!$B:$B,$B22,'Leave Records'!$D:$D,Config!$E$9,'Leave Records'!$K:$K,"Pending"))) -> 0 | O22: =IF($B22="","",L22-M22) -> 0 | P22: =IF($B22="","",IFERROR(Config!$F$10,0)) -> 0 | Q22: =IF($B22="","",IF(Config!$E$10="",0,SUMIFS('Leave Records'!$I:$I,'Leave Records'!$B:$B,$B22,'Leave Records'!$D:$D,Config!$E$10,'Leave Records'!$K:$K,"Approved"))) -> 0 | R22: =IF($B22="","",IF(Config!$E$10="",0,SUMIFS('Leave Records'!$I:$I,'Leave Records'!$B:$B,$B22,'Leave Records'!$D:$D,Config!$E$10,'Leave Records'!$K:$K,"Pending"))) -> 0 | S22: =IF($B22="","",P22-Q22) -> 0 | T22: =IF($B22="","",IFERROR(Config!$F$11,0)) -> 0 | U22: =IF($B22="","",IF(Config!$E$11="",0,SUMIFS('Leave Records'!$I:$I,'Leave Records'!$B:$B,$B22,'Leave Records'!$D:$D,Config!$E$11,'Leave Records'!$K:$K,"Approved"))) -> 0 | V22: =IF($B22="","",IF(Config!$E$11="",0,SUMIFS('Leave Records'!$I:$I,'Leave Records'!$B:$B,$B22,'Leave Records'!$D:$D,Config!$E$11,'Leave Records'!$K:$K,"Pending"))) -> 0 | W22: =IF($B22="","",T22-U22) -> 0 | X22: =IF($B22="","",E22+I22+M22+Q22+U22) -> 7
A23: =IF(B23="","",ROW()-4) -> 19 | B23: =IF(Config!$B$25="","",Config!$B$25) -> Samiya Hashem | C23: =IF(Config!$B$25="","",Config!$C$25) -> Teacher's Assistant | D23: =IF($B23="","",IFERROR(Config!$F$7,0)) -> 10 | E23: =IF($B23="","",IF(Config!$E$7="",0,SUMIFS('Leave Records'!$I:$I,'Leave Records'!$B:$B,$B23,'Leave Records'!$D:$D,Config!$E$7,'Leave Records'!$K:$K,"Approved"))) -> 1 | F23: =IF($B23="","",IF(Config!$E$7="",0,SUMIFS('Leave Records'!$I:$I,'Leave Records'!$B:$B,$B23,'Leave Records'!$D:$D,Config!$E$7,'Leave Records'!$K:$K,"Pending"))) -> 0 | G23: =IF($B23="","",D23-E23) -> 9 | H23: =IF($B23="","",IFERROR(Config!$F$8,0)) -> 5 | I23: =IF($B23="","",IF(Config!$E$8="",0,SUMIFS('Leave Records'!$I:$I,'Leave Records'!$B:$B,$B23,'Leave Records'!$D:$D,Config!$E$8,'Leave Records'!$K:$K,"Approved"))) -> 0 | J23: =IF($B23="","",IF(Config!$E$8="",0,SUMIFS('Leave Records'!$I:$I,'Leave Records'!$B:$B,$B23,'Leave Records'!$D:$D,Config!$E$8,'Leave Records'!$K:$K,"Pending"))) -> 0 | K23: =IF($B23="","",H23-I23) -> 5 | L23: =IF($B23="","",IFERROR(Config!$F$9,0)) -> 0 | M23: =IF($B23="","",IF(Config!$E$9="",0,SUMIFS('Leave Records'!$I:$I,'Leave Records'!$B:$B,$B23,'Leave Records'!$D:$D,Config!$E$9,'Leave Records'!$K:$K,"Approved"))) -> 0 | N23: =IF($B23="","",IF(Config!$E$9="",0,SUMIFS('Leave Records'!$I:$I,'Leave Records'!$B:$B,$B23,'Leave Records'!$D:$D,Config!$E$9,'Leave Records'!$K:$K,"Pending"))) -> 0 | O23: =IF($B23="","",L23-M23) -> 0 | P23: =IF($B23="","",IFERROR(Config!$F$10,0)) -> 0 | Q23: =IF($B23="","",IF(Config!$E$10="",0,SUMIFS('Leave Records'!$I:$I,'Leave Records'!$B:$B,$B23,'Leave Records'!$D:$D,Config!$E$10,'Leave Records'!$K:$K,"Approved"))) -> 0 | R23: =IF($B23="","",IF(Config!$E$10="",0,SUMIFS('Leave Records'!$I:$I,'Leave Records'!$B:$B,$B23,'Leave Records'!$D:$D,Config!$E$10,'Leave Records'!$K:$K,"Pending"))) -> 0 | S23: =IF($B23="","",P23-Q23) -> 0 | T23: =IF($B23="","",IFERROR(Config!$F$11,0)) -> 0 | U23: =IF($B23="","",IF(Config!$E$11="",0,SUMIFS('Leave Records'!$I:$I,'Leave Records'!$B:$B,$B23,'Leave Records'!$D:$D,Config!$E$11,'Leave Records'!$K:$K,"Approved"))) -> 0 | V23: =IF($B23="","",IF(Config!$E$11="",0,SUMIFS('Leave Records'!$I:$I,'Leave Records'!$B:$B,$B23,'Leave Records'!$D:$D,Config!$E$11,'Leave Records'!$K:$K,"Pending"))) -> 0 | W23: =IF($B23="","",T23-U23) -> 0 | X23: =IF($B23="","",E23+I23+M23+Q23+U23) -> 1
A24: =IF(B24="","",ROW()-4) -> 20 | B24: =IF(Config!$B$26="","",Config!$B$26) -> Humaira Tasnim | C24: =IF(Config!$B$26="","",Config!$C$26) | D24: =IF($B24="","",IFERROR(Config!$F$7,0)) -> 10 | E24: =IF($B24="","",IF(Config!$E$7="",0,SUMIFS('Leave Records'!$I:$I,'Leave Records'!$B:$B,$B24,'Leave Records'!$D:$D,Config!$E$7,'Leave Records'!$K:$K,"Approved"))) -> 7 | F24: =IF($B24="","",IF(Config!$E$7="",0,SUMIFS('Leave Records'!$I:$I,'Leave Records'!$B:$B,$B24,'Leave Records'!$D:$D,Config!$E$7,'Leave Records'!$K:$K,"Pending"))) -> 0 | G24: =IF($B24="","",D24-E24) -> 3 | H24: =IF($B24="","",IFERROR(Config!$F$8,0)) -> 5 | I24: =IF($B24="","",IF(Config!$E$8="",0,SUMIFS('Leave Records'!$I:$I,'Leave Records'!$B:$B,$B24,'Leave Records'!$D:$D,Config!$E$8,'Leave Records'!$K:$K,"Approved"))) -> 0 | J24: =IF($B24="","",IF(Config!$E$8="",0,SUMIFS('Leave Records'!$I:$I,'Leave Records'!$B:$B,$B24,'Leave Records'!$D:$D,Config!$E$8,'Leave Records'!$K:$K,"Pending"))) -> 0 | K24: =IF($B24="","",H24-I24) -> 5 | L24: =IF($B24="","",IFERROR(Config!$F$9,0)) -> 0 | M24: =IF($B24="","",IF(Config!$E$9="",0,SUMIFS('Leave Records'!$I:$I,'Leave Records'!$B:$B,$B24,'Leave Records'!$D:$D,Config!$E$9,'Leave Records'!$K:$K,"Approved"))) -> 0 | N24: =IF($B24="","",IF(Config!$E$9="",0,SUMIFS('Leave Records'!$I:$I,'Leave Records'!$B:$B,$B24,'Leave Records'!$D:$D,Config!$E$9,'Leave Records'!$K:$K,"Pending"))) -> 0 | O24: =IF($B24="","",L24-M24) -> 0 | P24: =IF($B24="","",IFERROR(Config!$F$10,0)) -> 0 | Q24: =IF($B24="","",IF(Config!$E$10="",0,SUMIFS('Leave Records'!$I:$I,'Leave Records'!$B:$B,$B24,'Leave Records'!$D:$D,Config!$E$10,'Leave Records'!$K:$K,"Approved"))) -> 0 | R24: =IF($B24="","",IF(Config!$E$10="",0,SUMIFS('Leave Records'!$I:$I,'Leave Records'!$B:$B,$B24,'Leave Records'!$D:$D,Config!$E$10,'Leave Records'!$K:$K,"Pending"))) -> 0 | S24: =IF($B24="","",P24-Q24) -> 0 | T24: =IF($B24="","",IFERROR(Config!$F$11,0)) -> 0 | U24: =IF($B24="","",IF(Config!$E$11="",0,SUMIFS('Leave Records'!$I:$I,'Leave Records'!$B:$B,$B24,'Leave Records'!$D:$D,Config!$E$11,'Leave Records'!$K:$K,"Approved"))) -> 0 | V24: =IF($B24="","",IF(Config!$E$11="",0,SUMIFS('Leave Records'!$I:$I,'Leave Records'!$B:$B,$B24,'Leave Records'!$D:$D,Config!$E$11,'Leave Records'!$K:$K,"Pending"))) -> 0 | W24: =IF($B24="","",T24-U24) -> 0 | X24: =IF($B24="","",E24+I24+M24+Q24+U24) -> 7
